<mujoco model="spider">
  <compiler angle="degree" coordinate="local" inertiafromgeom="true"/>
  <option integrator="RK4" timestep="0.01"/>
  <custom>
    <numeric data="0.0 0.0 0.55 1.0 0.0 0.0 0.0 0.0 1.0 0.0 -1.0 0.0 -1.0 0.0 1.0" name="init_qpos"/>
  </custom>
  <default>
    <joint armature="1" damping="1" limited="true"/>
    <!-- <geom conaffinity="0" condim="3" density="5.0" friction="1 0.5 0.5" margin="0.01" rgba="0.8 0.6 0.4 1"/> -->
    <geom conaffinity="0" condim="3" density="5.0" friction="3 1.5 1.5" margin="0.01" rgba="0.8 0.6 0.4 1"/>
  </default>
  <asset>
    <texture builtin="gradient" height="50" rgb1="1 1 1" rgb2="0 0 0" type="skybox" width="50"/>
    <texture builtin="flat" height="1278" mark="cross" markrgb="1 1 1" name="texgeom" random="0.01" rgb1="0.8 0.6 0.4" rgb2="0.8 0.6 0.4" type="cube" width="127"/>
    <texture builtin="checker" height="50" name="texplane" rgb1="0 0 0" rgb2="0.8 0.8 0.8" type="2d" width="50"/>
    <material name="MatPlane" reflectance="0.5" shininess="1" specular="1" texrepeat="60 60" texture="texplane"/>
    <material name="geom" texture="texgeom" texuniform="true"/>
  </asset>

  <worldbody>
    <light cutoff="50" diffuse="1 1 1" dir="-0 0 -1.3" directional="true" exponent="1" pos="0 0 1.3" specular=".1 .1 .1"/>
    <geom conaffinity="1" condim="3" material="MatPlane" name="floor" pos="0 0 0" rgba="0.8 0.9 0.8 1" size="40 40 40" type="plane"/>
    
    <body name="torso" pos="0 0 0.75">
      <camera name="track" mode="trackcom" pos="0 -3 0.3" xyaxes="5 0 0 0 0 -1"/>
        <site name="torso_site"/>
      <geom name="torso_geom" pos="0 0 0" size="0.3" type="sphere"/>
      <joint armature="0" damping="0" limited="false" margin="0.01" name="root" pos="0 0 0" type="free"/>
      
    <body name="butt" pos="0.0 -0.6 0.3">        
        <geom name="butt_geom" pos="0 0 0" size="0.4" type="sphere"/>
    </body>

    <!--  -->

    <body name="front_left_leg" pos="0 0 0">
        <geom fromto="0.0 0.0 0.0 0.2 0.2 0.0" name="aux_1_geom" size="0.08" type="capsule"/>        
        
        <body name="aux_1" pos="0.2 0.2 0.0">
          <joint axis="0 0 1" name="hip_1" pos="0.0 0.0 0.0" range="-30 40" type="hinge"/>
          <geom fromto="0.0 0.0 0.0 0.2 0.2 0.2" name="left_leg_geom" size="0.08" type="capsule"/>          
        
          <body pos="0.2 0.2 0.2">
            <joint axis="-1 1 0" name="ankle_1" pos="0.0 0.0 0.0" range="-30 70" type="hinge"/>
            <geom fromto="0.0 0.0 0.0 0.5 0.5 -0.2" name="left_ankle_geom" size="0.08" type="capsule"/>          
        
            <body name="front_left_end" pos="0.5 0.5 -0.2">
              <joint axis="-1 1 0" name="ankle_1b" pos="0.0 0.0 0.0" range="-30 70" type="hinge"/>
              <geom fromto="0.0 0.0 0.0 0.4 0.4 -0.7" name="left_ankle_b_geom" size="0.08" type="capsule"/>            
            </body>
          
          </body>
        </body>
    </body>

    <body name="front_right_leg" pos="0 0 0">
        <geom fromto="0.0 0.0 0.0 -0.2 0.2 0.0" name="aux_2_geom" size="0.08" type="capsule"/>        
        
        <body name="aux_2" pos="-0.2 0.2 0">
          <joint axis="0 0 1" name="hip_2" pos="0.0 0.0 0.0" range="-40 30" type="hinge"/>
          <geom fromto="0.0 0.0 0.0 -0.2 0.2 0.2" name="right_leg_geom" size="0.08" type="capsule"/>        
        
          <body pos="-0.2 0.2 0.2">
            <joint axis="1 1 0" name="ankle_2" pos="0.0 0.0 0.0" range="-70 30" type="hinge"/>
            <geom fromto="0.0 0.0 0.0 -0.5 0.5 -0.2" name="right_ankle_geom" size="0.08" type="capsule"/>          
        
            <body name="front_right_end" pos="-0.5 0.5 -0.2">
              <joint axis="1 1 0" name="ankle_2b" pos="0.0 0.0 0.0" range="-70 30" type="hinge"/>
              <geom fromto="0.0 0.0 0.0 -0.4 0.4 -0.7" name="right_ankle_b_geom" size="0.08" type="capsule"/>
            </body>
          </body>
        </body>
      </body>

    <!--  -->

    <body name="mid_back_left_leg" pos="0 0 0">
        <geom fromto="0.0 0.0 0.0 0.3 -0.1 0.1" name="nub2" size="0.08" type="capsule"/>        

        <body name="aux_8" pos="0.3 -0.1 0.1">
          <joint axis="0 0 1" name="hip_8" pos="0.0 0.0 0.0" range="-50 50" type="hinge"/>
          <geom fromto="0.0 0.0 0.0 0.3 -0.1 0.1" name="mid_back_left_leg_geom" size="0.08" type="capsule"/>      

          <body pos="0.3 -0.1 0.1">
            <joint axis="0 -1 0" name="ankle_8" pos="0.0 0.0 0.0" range="-70 30" type="hinge"/>
            <geom fromto="0.0 0.0 0.0 0.5 -0.1 0.0" name="mid_back_left_ankle_geom" size="0.08" type="capsule"/>              

            <body name="mid_back_left_end" pos="0.5 -0.1 0.0">
                <joint axis="0 -1 0" name="ankle_8b" pos="0.0 0.0 0.0" range="-70 30" type="hinge"/>
                <geom fromto="0.0 0.0 0.0 0.7 -0.1 -0.5" name="mid_back_left_ankle_b_geom" size="0.08" type="capsule"/>              
            </body>
          </body>
        </body>
    </body>

    <body name="mid_back_right_leg" pos="0 0 0">
        <geom fromto="0.0 0.0 0.0 -0.3 -0.1 0.1" name="nub4" size="0.08" type="capsule"/>        

        <body name="aux_7" pos="-0.3 -0.1 0.1">
          <joint axis="0 0 1" name="hip_7" pos="0.0 0.0 0.0" range="-50 50" type="hinge"/>
          <geom fromto="0.0 0.0 0.0 -0.3 -0.1 0.1" name="mid_back_right_leg_geom" size="0.08" type="capsule"/>      

          <body pos="-0.3 -0.1 0.1">
            <joint axis="0 1 0" name="ankle_7" pos="0.0 0.0 0.0" range="-30 70" type="hinge"/>
            <geom fromto="0.0 0.0 0.0 -0.5 -0.1 0.0" name="mid_back_right_ankle_geom" size="0.08" type="capsule"/>              

            <body name="mid_back_right_end" pos="-0.5 -0.1 0.0">
                <joint axis="0 1 0" name="ankle_7b" pos="0.0 0.0 0.0" range="-30 70" type="hinge"/>
                <geom fromto="0.0 0.0 0.0 -0.7 -0.1 -0.7" name="mid_back_right_ankle_b_geom" size="0.08" type="capsule"/>              
            </body>
          </body>
        </body>
    </body>


    <!--  -->


    <body name="mid_front_left_leg" pos="0 0 0">
        <geom fromto="0.0 0.0 0.0 0.3 0.1 0.1" name="nub1" size="0.08" type="capsule"/>        

        <body name="aux_5" pos="0.3 0.1 0.1">
          <joint axis="0 0 1" name="hip_5" pos="0.0 0.0 0.0" range="-50 50" type="hinge"/>
          <geom fromto="0.0 0.0 0.0 0.3 0.1 0.1" name="mid_front_left_leg_geom" size="0.08" type="capsule"/>      

          <body pos="0.3 0.1 0.1">
            <joint axis="0 -1 0" name="ankle_5" pos="0.0 0.0 0.0" range="-70 30" type="hinge"/>
            <geom fromto="0.0 0.0 0.0 0.5 0.1 0.0" name="mid_front_left_ankle_geom" size="0.08" type="capsule"/>              

            <body name="mid_front_left_end" pos="0.5 0.1 0.0">
                <joint axis="0 -1 0" name="ankle_5b" pos="0.0 0.0 0.0" range="-70 30" type="hinge"/>
                <geom fromto="0.0 0.0 0.0 0.6 0.1 -0.5" name="mid_front_left_ankle_b_geom" size="0.08" type="capsule"/>              
            </body>
          </body>
        </body>
    </body>


    <body name="mid_front_right_leg" pos="0 0 0">
        <geom fromto="0.0 0.0 0.0 -0.3 0.1 0.1" name="nub3" size="0.08" type="capsule"/>        

        <body name="aux_6" pos="-0.3 0.1 0.1">
          <joint axis="0 0 1" name="hip_6" pos="0.0 0.0 0.0" range="-50 50" type="hinge"/>
          <geom fromto="0.0 0.0 0.0 -0.3 0.1 0.1" name="mid_front_right_leg_geom" size="0.08" type="capsule"/>      

          <body pos="-0.3 0.1 0.1">
            <joint axis="0 1 0" name="ankle_6" pos="0.0 0.0 0.0" range="-70 30" type="hinge"/>
            <geom fromto="0.0 0.0 0.0 -0.5 0.1 0.0" name="mid_front_right_ankle_geom" size="0.08" type="capsule"/>              

            <body name="mid_front_right_end" pos="-0.5 0.1 0.0">
                <joint axis="0 1 0" name="ankle_6b" pos="0.0 0.0 0.0" range="-70 30" type="hinge"/>
                <geom fromto="0.0 0.0 0.0 -0.6 0.1 -0.5" name="mid_front_right_ankle_b_geom" size="0.08" type="capsule"/>              
            </body>
          </body>
        </body>
    </body>   
      
    <!--  -->

    <body name="left_back_leg" pos="0 0 0">
        <geom fromto="0.0 0.0 0.0 -0.2 -0.2 0.3" name="aux_3_geom" size="0.08" type="capsule"/>
        
        <body name="aux_3" pos="-0.2 -0.2 0.3">
          <joint axis="0 0 1" name="hip_3" pos="0.0 0.0 0.0" range="-50 30" type="hinge"/>
          <geom fromto="0.0 0.0 0.0 -0.4 -0.4 0.3" name="back_leg_geom" size="0.08" type="capsule"/>
          
          <body pos="-0.4 -0.4 0.3">
            <joint axis="-1 1 0" name="ankle_3" pos="0.0 0.0 0.0" range="-70 30" type="hinge"/>
            <geom fromto="0.0 0.0 0.0 -0.7 -0.7 -0.6" name="third_ankle_geom" size="0.08" type="capsule"/>
            
            <body  name="left_back_end" pos="-0.7 -0.7 -0.6">
              <joint axis="-1 1 0" name="ankle_3b" pos="0.0 0.0 0.0" range="-70 30" type="hinge"/>
              <geom fromto="0.0 0.0 0.0 -0.4 -0.4 -.7" name="third_ankle_b_geom" size="0.08" type="capsule"/>
            </body>
          </body>
        </body>
      </body>


      <body name="right_back_leg" pos="0 0 0">
        <geom fromto="0.0 0.0 0.0 0.2 -0.2 0.3" name="aux_4_geom" size="0.08" type="capsule"/>
        
        <body name="aux_4" pos="0.2 -0.2 0.3">
          <joint axis="0 0 1" name="hip_4" pos="0.0 0.0 0.0" range="-50 30" type="hinge"/>
          <geom fromto="0.0 0.0 0.0 0.4 -0.4 0.3" name="rightback_leg_geom" size="0.08" type="capsule"/>
          
          <body pos="0.4 -0.4 0.3">
            <joint axis="1 1 0" name="ankle_4" pos="0.0 0.0 0.0" range="-30 70" type="hinge"/>
            <geom fromto="0.0 0.0 0.0 0.7 -0.7 -0.6" name="fourth_ankle_geom" size="0.08" type="capsule"/>
            
            <body name="right_back_end" pos="0.7 -0.7 -0.6">
              <joint axis="1 1 0" name="ankle_4b" pos="0.0 0.0 0.0" range="-30 70" type="hinge"/>
              <geom fromto="0.0 0.0 0.0 0.4 -0.4 -0.7" name="fourth_ankle_b_geom" size="0.08" type="capsule"/>
            </body>
          </body>
        </body>
      </body>
    </body>

  </worldbody>

    <sensor>
        <accelerometer name="accelerometer" site="torso_site"/>
        <gyro name="gyro" site="torso_site"/>
        <!-- <⁠framezaxis name="⁠framezaxis" site="torso_site"/> -->
    </sensor>

  <actuator>
    <motor ctrllimited="true" ctrlrange="-1.0 1.0" joint="hip_4" gear="50"/>
    <motor ctrllimited="true" ctrlrange="-1.0 1.0" joint="ankle_4" gear="50"/>
    <motor ctrllimited="true" ctrlrange="-1.0 1.0" joint="ankle_4b" gear="50"/>
    <motor ctrllimited="true" ctrlrange="-1.0 1.0" joint="hip_1" gear="50"/>
    <motor ctrllimited="true" ctrlrange="-1.0 1.0" joint="ankle_1" gear="50"/>
    <motor ctrllimited="true" ctrlrange="-1.0 1.0" joint="ankle_1b" gear="50"/>
    <motor ctrllimited="true" ctrlrange="-1.0 1.0" joint="hip_2" gear="50"/>
    <motor ctrllimited="true" ctrlrange="-1.0 1.0" joint="ankle_2" gear="50"/>
    <motor ctrllimited="true" ctrlrange="-1.0 1.0" joint="ankle_2b" gear="50"/>
    <motor ctrllimited="true" ctrlrange="-1.0 1.0" joint="hip_3" gear="50"/>
    <motor ctrllimited="true" ctrlrange="-1.0 1.0" joint="ankle_3" gear="50"/>
    <motor ctrllimited="true" ctrlrange="-1.0 1.0" joint="ankle_3b" gear="50"/>
    <motor ctrllimited="true" ctrlrange="-1.0 1.0" joint="hip_5" gear="50"/>
    <motor ctrllimited="true" ctrlrange="-1.0 1.0" joint="ankle_5" gear="50"/>
    <motor ctrllimited="true" ctrlrange="-1.0 1.0" joint="ankle_5b" gear="50"/>
    <motor ctrllimited="true" ctrlrange="-1.0 1.0" joint="hip_6" gear="50"/>
    <motor ctrllimited="true" ctrlrange="-1.0 1.0" joint="ankle_6" gear="50"/>
    <motor ctrllimited="true" ctrlrange="-1.0 1.0" joint="ankle_6b" gear="50"/>
    <motor ctrllimited="true" ctrlrange="-1.0 1.0" joint="hip_7" gear="50"/>
    <motor ctrllimited="true" ctrlrange="-1.0 1.0" joint="ankle_7" gear="50"/>
    <motor ctrllimited="true" ctrlrange="-1.0 1.0" joint="ankle_7b" gear="50"/>
    <motor ctrllimited="true" ctrlrange="-1.0 1.0" joint="hip_8" gear="50"/>
    <motor ctrllimited="true" ctrlrange="-1.0 1.0" joint="ankle_8" gear="50"/>
    <motor ctrllimited="true" ctrlrange="-1.0 1.0" joint="ankle_8b" gear="50"/>

  </actuator>
</mujoco>
